✅ wandb initialized!
Epoch 1/50:   0%|                                                                  | 0/93 [05:34<?, ?it/s, loss=2.5004]Traceback (most recent call last):
Epoch 1 Loss: 260.9689 | Validation Accuracy: 9.78%
✅ Best model saved!
  File "C:\Users\rheehs\anaconda3\envs\HairNet\lib\runpy.py", line 196, in _run_module_as_main
    return _run_code(code, main_globals, None,
  File "C:\Users\rheehs\anaconda3\envs\HairNet\lib\runpy.py", line 86, in _run_code
    exec(code, run_globals)
  File "C:\Users\rheehs\GIST\4-1\딥러닝\HairNet\train\train_wandb.py", line 99, in <module>
    train()
  File "C:\Users\rheehs\GIST\4-1\딥러닝\HairNet\train\train_wandb.py", line 91, in train
    wandb.save("best_model.pth")
  File "C:\Users\rheehs\anaconda3\envs\HairNet\lib\site-packages\wandb\sdk\wandb_run.py", line 406, in wrapper
    return func(self, *args, **kwargs)
  File "C:\Users\rheehs\anaconda3\envs\HairNet\lib\site-packages\wandb\sdk\wandb_run.py", line 464, in wrapper_fn
    return func(self, *args, **kwargs)
  File "C:\Users\rheehs\anaconda3\envs\HairNet\lib\site-packages\wandb\sdk\wandb_run.py", line 451, in wrapper
    return func(self, *args, **kwargs)
  File "C:\Users\rheehs\anaconda3\envs\HairNet\lib\site-packages\wandb\sdk\wandb_run.py", line 2175, in save
    return self._save(
  File "C:\Users\rheehs\anaconda3\envs\HairNet\lib\site-packages\wandb\sdk\wandb_run.py", line 2234, in _save
    target_path.symlink_to(source_path)
  File "C:\Users\rheehs\anaconda3\envs\HairNet\lib\pathlib.py", line 1255, in symlink_to
    self._accessor.symlink(target, self, target_is_directory)
OSError: [WinError 1314] 클라이언트가 필요한 권한을 가지고 있지 않습니다: 'C:\\Users\\rheehs\\GIST\\4-1\\딥러닝\\HairNet\\best_model.pth' -> 'C:\\Users\\rheehs\\GIST\\4-1\\딥러닝\\HairNet\\wandb\\run-20250524_010553-65miaba0\\files\\best_model.pth'
Traceback (most recent call last):
  File "C:\Users\rheehs\anaconda3\envs\HairNet\lib\runpy.py", line 196, in _run_module_as_main
    return _run_code(code, main_globals, None,
  File "C:\Users\rheehs\anaconda3\envs\HairNet\lib\runpy.py", line 86, in _run_code
    exec(code, run_globals)
  File "C:\Users\rheehs\GIST\4-1\딥러닝\HairNet\train\train_wandb.py", line 99, in <module>
    train()
  File "C:\Users\rheehs\GIST\4-1\딥러닝\HairNet\train\train_wandb.py", line 91, in train
    wandb.save("best_model.pth")
  File "C:\Users\rheehs\anaconda3\envs\HairNet\lib\site-packages\wandb\sdk\wandb_run.py", line 406, in wrapper
    return func(self, *args, **kwargs)
  File "C:\Users\rheehs\anaconda3\envs\HairNet\lib\site-packages\wandb\sdk\wandb_run.py", line 464, in wrapper_fn
    return func(self, *args, **kwargs)
  File "C:\Users\rheehs\anaconda3\envs\HairNet\lib\site-packages\wandb\sdk\wandb_run.py", line 451, in wrapper
    return func(self, *args, **kwargs)
  File "C:\Users\rheehs\anaconda3\envs\HairNet\lib\site-packages\wandb\sdk\wandb_run.py", line 2175, in save
    return self._save(
  File "C:\Users\rheehs\anaconda3\envs\HairNet\lib\site-packages\wandb\sdk\wandb_run.py", line 2234, in _save
    target_path.symlink_to(source_path)
  File "C:\Users\rheehs\anaconda3\envs\HairNet\lib\pathlib.py", line 1255, in symlink_to
    self._accessor.symlink(target, self, target_is_directory)
OSError: [WinError 1314] 클라이언트가 필요한 권한을 가지고 있지 않습니다: 'C:\\Users\\rheehs\\GIST\\4-1\\딥러닝\\HairNet\\best_model.pth' -> 'C:\\Users\\rheehs\\GIST\\4-1\\딥러닝\\HairNet\\wandb\\run-20250524_010553-65miaba0\\files\\best_model.pth'
